Workbook
Name Slicer_Sector: #N/A

Sheet Dashboard
A1: Insight 1.Showing the highest broader category in three sector in the last month is food exp

Sheet Cpi data 
A1: Sector | B1: Year | C1: Month | D1: short month and year | E1: date | F1: Pre/Post Covid | G1: Cereals and products | H1: Meat and fish | I1: Egg | J1: Milk and products | K1: Oils and fats | L1: Fruits | M1: Vegetables | N1: Pulses and products | O1: Sugar and Confectionery | P1: Spices | Q1: Non-alcoholic beverages | R1: Prepared meals, snacks, sweets etc. | S1: Food and beverages | T1: Pan, tobacco and intoxicants | U1: Clothing | V1: Footwear | W1: Clothing and footwear | X1: Housing | Y1: Fuel and light | Z1: Household goods and services | AA1: Health | AB1: Transport and communication | AC1: Recreation and amusement | AD1: Education | AE1: Personal care and effects | AF1: Miscellaneous | AG1: General index | AH1: Total Expences | AI1: sum of others | AJ1: sum of clothing | AK1: Sum Housing Exepences | AL1: Sum of food expences | AM1: Average Other Expences | AN1: Average Housing Expences | AO1: Average Food Expences
A2: Rural | B2: 2013 | C2: January | D2: =TEXT(DATE(B2, MONTH(1&C2), 1), "mmm-yy") -> Jan-13 | E2: 41275 | F2: Pre covid | G2: 107.5 | H2: 106.3 | I2: 108.1 | J2: 104.9 | K2: 106.1 | L2: 103.9 | M2: 101.9 | N2: 106.1 | O2: 106.8 | P2: 103.1 | Q2: 104.8 | R2: 106.7 | S2: 105.5 | T2: 105.1 | U2: 106.5 | V2: 105.8 | W2: 106.4 | X2: ='Handle missing value sheet only'!$C$1 -> 139.27097 | Y2: 105.5 | Z2: 104.8 | AA2: 104 | AB2: 103.3 | AC2: 103.4 | AD2: 103.8 | AE2: 104.7 | AF2: 104 | AG2: 105.1 | AH2: =SUM(X2:AF2,G2:V2) -> 2661.871 | AI2: =SUM(AF2,AE2,AD2,AC2) -> 415.9 | AJ2: =SUM(V2,U2) -> 212.3 | AK2: =SUM(Z2,X2) -> 244.07097 | AL2: =SUM(G2:T2) -> 1476.8 | AM2: =AVERAGE(AF2,AE2,AD2,AC2) -> 103.975 | AN2: =AVERAGE(X2,Z2) -> 122.03548 | AO2: 105.48571
A3: Urban | B3: 2013 | C3: January | D3: =TEXT(DATE(B3, MONTH(1&C3), 1), "mmm-yy") -> Jan-13 | E3: 41275 | F3: Pre covid | G3: 110.5 | H3: 109.1 | I3: 113 | J3: 103.6 | K3: 103.4 | L3: 102.3 | M3: 102.9 | N3: 105.8 | O3: 105.1 | P3: 101.8 | Q3: 105.1 | R3: 107.9 | S3: 105.9 | T3: 105.2 | U3: 105.9 | V3: 105 | W3: 105.8 | X3: 100.3 | Y3: 105.4 | Z3: 104.8 | AA3: 104.1 | AB3: 103.2 | AC3: 102.9 | AD3: 103.5 | AE3: 104.3 | AF3: 103.7 | AG3: 104 | AH3: =SUM(X3:AF3,G3:V3) -> 2624.7 | AI3: =SUM(AF3,AE3,AD3,AC3) -> 414.4 | AJ3: =SUM(V3,U3) -> 210.9 | AK3: =SUM(Z3,X3) -> 205.1 | AL3: =SUM(G3:T3) -> 1481.6 | AM3: =AVERAGE(AF3,AE3,AD3,AC3) -> 103.6 | AN3: =AVERAGE(X3,Z3) -> 102.55 | AO3: 105.82857
A4: Rural+Urban | B4: 2013 | C4: January | D4: =TEXT(DATE(B4, MONTH(1&C4), 1), "mmm-yy") -> Jan-13 | E4: 41275 | F4: Pre covid | G4: 108.4 | H4: 107.3 | I4: 110 | J4: 104.4 | K4: 105.1 | L4: 103.2 | M4: 102.2 | N4: 106 | O4: 106.2 | P4: 102.7 | Q4: 104.9 | R4: 107.3 | S4: 105.6 | T4: 105.1 | U4: 106.3 | V4: 105.5 | W4: 106.2 | X4: 100.3 | Y4: 105.5 | Z4: 104.8 | AA4: 104 | AB4: 103.2 | AC4: 103.1 | AD4: 103.6 | AE4: 104.5 | AF4: 103.9 | AG4: 104.6 | AH4: =SUM(X4:AF4,G4:V4) -> 2623.1 | AI4: =SUM(AF4,AE4,AD4,AC4) -> 415.1 | AJ4: =SUM(V4,U4) -> 211.8 | AK4: =SUM(Z4,X4) -> 205.1 | AL4: =SUM(G4:T4) -> 1478.4 | AM4: =AVERAGE(AF4,AE4,AD4,AC4) -> 103.775 | AN4: =AVERAGE(X4,Z4) -> 102.55 | AO4: 105.6
A5: Rural | B5: 2013 | C5: February | D5: =TEXT(DATE(B5, MONTH(1&C5), 1), "mmm-yy") -> Feb-13 | E5: 41306 | F5: Pre covid | G5: 109.2 | H5: 108.7 | I5: 110.2 | J5: 105.4 | K5: 106.7 | L5: 104 | M5: 102.4 | N5: 105.9 | O5: 105.7 | P5: 103.1 | Q5: 105.1 | R5: 107.7 | S5: 106.3 | T5: 105.6 | U5: 107.1 | V5: 106.3 | W5: 107 | X5: ='Handle missing value sheet only'!$C$1 -> 139.27097 | Y5: 106.2 | Z5: 105.2 | AA5: 104.4 | AB5: 103.9 | AC5: 104 | AD5: 104.1 | AE5: 104.6 | AF5: 104.4 | AG5: 105.8 | AH5: =SUM(X5:AF5,G5:V5) -> 2675.471 | AI5: =SUM(AF5,AE5,AD5,AC5) -> 417.1 | AJ5: =SUM(V5,U5) -> 213.4 | AK5: =SUM(Z5,X5) -> 244.47097 | AL5: =SUM(G5:T5) -> 1486 | AM5: =AVERAGE(AF5,AE5,AD5,AC5) -> 104.275 | AN5: =AVERAGE(X5,Z5) -> 122.23548 | AO5: 106.14286
A6: Urban | B6: 2013 | C6: February | D6: =TEXT(DATE(B6, MONTH(1&C6), 1), "mmm-yy") -> Feb-13 | E6: 41306 | F6: Pre covid | G6: 112.9 | H6: 112.9 | I6: 116.9 | J6: 104 | K6: 103.5 | L6: 103.1 | M6: 104.9 | N6: 104.1 | O6: 103.8 | P6: 102.3 | Q6: 106 | R6: 109 | S6: 107.2 | T6: 106 | U6: 106.6 | V6: 105.5 | W6: 106.4 | X6: 100.4 | Y6: 105.7 | Z6: 105.2 | AA6: 104.7 | AB6: 104.4 | AC6: 103.3 | AD6: 103.7 | AE6: 104.3 | AF6: 104.3 | AG6: 104.7 | AH6: =SUM(X6:AF6,G6:V6) -> 2644.7 | AI6: =SUM(AF6,AE6,AD6,AC6) -> 415.6 | AJ6: =SUM(V6,U6) -> 212.1 | AK6: =SUM(Z6,X6) -> 205.6 | AL6: =SUM(G6:T6) -> 1496.6 | AM6: =AVERAGE(AF6,AE6,AD6,AC6) -> 103.9 | AN6: =AVERAGE(X6,Z6) -> 102.8 | AO6: 106.9
A7: Rural+Urban | B7: 2013 | C7: February | D7: =TEXT(DATE(B7, MONTH(1&C7), 1), "mmm-yy") -> Feb-13 | E7: 41306 | F7: Pre covid | G7: 110.4 | H7: 110.2 | I7: 112.8 | J7: 104.9 | K7: 105.5 | L7: 103.6 | M7: 103.2 | N7: 105.3 | O7: 105.1 | P7: 102.8 | Q7: 105.5 | R7: 108.3 | S7: 106.6 | T7: 105.7 | U7: 106.9 | V7: 106 | W7: 106.8 | X7: 100.4 | Y7: 106 | Z7: 105.2 | AA7: 104.5 | AB7: 104.2 | AC7: 103.6 | AD7: 103.9 | AE7: 104.5 | AF7: 104.4 | AG7: 105.3 | AH7: =SUM(X7:AF7,G7:V7) -> 2639.5 | AI7: =SUM(AF7,AE7,AD7,AC7) -> 416.4 | AJ7: =SUM(V7,U7) -> 212.9 | AK7: =SUM(Z7,X7) -> 205.6 | AL7: =SUM(G7:T7) -> 1489.9 | AM7: =AVERAGE(AF7,AE7,AD7,AC7) -> 104.1 | AN7: =AVERAGE(X7,Z7) -> 102.8 | AO7: 106.42143
A8: Rural | B8: 2013 | C8: March | D8: =TEXT(DATE(B8, MONTH(1&C8), 1), "mmm-yy") -> Mar-13 | E8: 41334 | F8: Pre covid | G8: 110.2 | H8: 108.8 | I8: 109.9 | J8: 105.6 | K8: 106.2 | L8: 105.7 | M8: 101.4 | N8: 105.7 | O8: 105 | P8: 103.3 | Q8: 105.6 | R8: 108.2 | S8: 106.6 | T8: 106.5 | U8: 107.6 | V8: 106.8 | W8: 107.5 | X8: ='Handle missing value sheet only'!$C$1 -> 139.27097 | Y8: 106.1 | Z8: 105.6 | AA8: 104.7 | AB8: 104.6 | AC8: 104 | AD8: 104.3 | AE8: 104.3 | AF8: 104.6 | AG8: 106 | AH8: =SUM(X8:AF8,G8:V8) -> 2680.571 | AI8: =SUM(AF8,AE8,AD8,AC8) -> 417.2 | AJ8: =SUM(V8,U8) -> 214.4 | AK8: =SUM(Z8,X8) -> 244.87097 | AL8: =SUM(G8:T8) -> 1488.7 | AM8: =AVERAGE(AF8,AE8,AD8,AC8) -> 104.3 | AN8: =AVERAGE(X8,Z8) -> 122.43548 | AO8: 106.33571
A9: Urban | B9: 2013 | C9: March | D9: =TEXT(DATE(B9, MONTH(1&C9), 1), "mmm-yy") -> Mar-13 | E9: 41334 | F9: Pre covid | G9: 113.9 | H9: 111.4 | I9: 113.2 | J9: 104.3 | K9: 102.7 | L9: 104.9 | M9: 103.8 | N9: 103.5 | O9: 102.6 | P9: 102.4 | Q9: 107 | R9: 109.8 | S9: 107.3 | T9: 106.8 | U9: 107.2 | V9: 106 | W9: 107 | X9: 100.4 | Y9: 106 | Z9: 105.7 | AA9: 105.2 | AB9: 105.5 | AC9: 103.5 | AD9: 103.8 | AE9: 104.2 | AF9: 104.9 | AG9: 105 | AH9: =SUM(X9:AF9,G9:V9) -> 2646 | AI9: =SUM(AF9,AE9,AD9,AC9) -> 416.4 | AJ9: =SUM(V9,U9) -> 213.2 | AK9: =SUM(Z9,X9) -> 206.1 | AL9: =SUM(G9:T9) -> 1493.6 | AM9: =AVERAGE(AF9,AE9,AD9,AC9) -> 104.1 | AN9: =AVERAGE(X9,Z9) -> 103.05 | AO9: 106.68571
A10: Rural+Urban | B10: 2013 | C10: March | D10: =TEXT(DATE(B10, MONTH(1&C10), 1), "mmm-yy") -> Mar-13 | E10: 41334 | F10: Pre covid | G10: 111.4 | H10: 109.7 | I10: 111.2 | J10: 105.1 | K10: 104.9 | L10: 105.3 | M10: 102.2 | N10: 105 | O10: 104.2 | P10: 103 | Q10: 106.2 | R10: 108.9 | S10: 106.9 | T10: 106.6 | U10: 107.4 | V10: 106.5 | W10: 107.3 | X10: 100.4 | Y10: 106.1 | Z10: 105.6 | AA10: 104.9 | AB10: 105.1 | AC10: 103.7 | AD10: 104 | AE10: 104.3 | AF10: 104.7 | AG10: 105.5 | AH10: =SUM(X10:AF10,G10:V10) -> 2643.3 | AI10: =SUM(AF10,AE10,AD10,AC10) -> 416.7 | AJ10: =SUM(V10,U10) -> 213.9 | AK10: =SUM(Z10,X10) -> 206 | AL10: =SUM(G10:T10) -> 1490.6 | AM10: =AVERAGE(AF10,AE10,AD10,AC10) -> 104.175 | AN10: =AVERAGE(X10,Z10) -> 103 | AO10: 106.47143
A11: Rural | B11: 2013 | C11: April | D11: =TEXT(DATE(B11, MONTH(1&C11), 1), "mmm-yy") -> Apr-13 | E11: 41365 | F11: Pre covid | G11: 110.2 | H11: 109.5 | I11: 106.9 | J11: 106.3 | K11: 105.7 | L11: 108.3 | M11: 103.4 | N11: 105.7 | O11: 104.2 | P11: 103.2 | Q11: 106.5 | R11: 108.8 | S11: 107.1 | T11: 107.1 | U11: 108.1 | V11: 107.4 | W11: 108 | X11: ='Handle missing value sheet only'!$C$1 -> 139.27097 | Y11: 106.5 | Z11: 106.1 | AA11: 105.1 | AB11: 104.4 | AC11: 104.5 | AD11: 104.8 | AE11: 102.7 | AF11: 104.6 | AG11: 106.4 | AH11: =SUM(X11:AF11,G11:V11) -> 2686.371 | AI11: =SUM(AF11,AE11,AD11,AC11) -> 416.6 | AJ11: =SUM(V11,U11) -> 215.5 | AK11: =SUM(Z11,X11) -> 245.37097 | AL11: =SUM(G11:T11) -> 1492.9 | AM11: =AVERAGE(AF11,AE11,AD11,AC11) -> 104.15 | AN11: =AVERAGE(X11,Z11) -> 122.68548 | AO11: 106.63571
A12: Urban | B12: 2013 | C12: April | D12: =TEXT(DATE(B12, MONTH(1&C12), 1), "mmm-yy") -> Apr-13 | E12: 41365 | F12: Pre covid | G12: 114.6 | H12: 113.4 | I12: 106 | J12: 104.7 | K12: 102.1 | L12: 109.5 | M12: 109.7 | N12: 104.6 | O12: 102 | P12: 103.5 | Q12: 108.2 | R12: 110.6 | S12: 108.8 | T12: 108.5 | U12: 107.9 | V12: 106.4 | W12: 107.7 | X12: 100.5 | Y12: 106.4 | Z12: 106.5 | AA12: 105.7 | AB12: 105 | AC12: 104 | AD12: 105.2 | AE12: 103.2 | AF12: 105.1 | AG12: 105.7 | AH12: =SUM(X12:AF12,G12:V12) -> 2662.1 | AI12: =SUM(AF12,AE12,AD12,AC12) -> 417.5 | AJ12: =SUM(V12,U12) -> 214.3 | AK12: =SUM(Z12,X12) -> 207 | AL12: =SUM(G12:T12) -> 1506.2 | AM12: =AVERAGE(AF12,AE12,AD12,AC12) -> 104.375 | AN12: =AVERAGE(X12,Z12) -> 103.5 | AO12: 107.58571
A13: Rural+Urban | B13: 2013 | C13: April | D13: =TEXT(DATE(B13, MONTH(1&C13), 1), "mmm-yy") -> Apr-13 | E13: 41365 | F13: Pre covid | G13: 111.6 | H13: 110.9 | I13: 106.6 | J13: 105.7 | K13: 104.4 | L13: 108.9 | M13: 105.5 | N13: 105.3 | O13: 103.5 | P13: 103.3 | Q13: 107.2 | R13: 109.6 | S13: 107.7 | T13: 107.5 | U13: 108 | V13: 107 | W13: 107.9 | X13: 100.5 | Y13: 106.5 | Z13: 106.3 | AA13: 105.3 | AB13: 104.7 | AC13: 104.2 | AD13: 105 | AE13: 102.9 | AF13: 104.8 | AG13: 106.1 | AH13: =SUM(X13:AF13,G13:V13) -> 2652.9 | AI13: =SUM(AF13,AE13,AD13,AC13) -> 416.9 | AJ13: =SUM(V13,U13) -> 215 | AK13: =SUM(Z13,X13) -> 206.8 | AL13: =SUM(G13:T13) -> 1497.7 | AM13: =AVERAGE(AF13,AE13,AD13,AC13) -> 104.225 | AN13: =AVERAGE(X13,Z13) -> 103.4 | AO13: 106.97857
A14: Rural | B14: 2013 | C14: May | D14: =TEXT(DATE(B14, MONTH(1&C14), 1), "mmm-yy") -> May-13 | E14: 41395 | F14: Pre covid | G14: 110.9 | H14: 109.8 | I14: 105.9 | J14: 107.5 | K14: 105.3 | L14: 108.1 | M14: 107.3 | N14: 106.1 | O14: 103.7 | P14: 104 | Q14: 107.4 | R14: 109.9 | S14: 108.1 | T14: 108.1 | U14: 108.8 | V14: 107.9 | W14: 108.6 | X14: ='Handle missing value sheet only'!$C$1 -> 139.27097 | Y14: 107.5 | Z14: 106.8 | AA14: 105.7 | AB14: 104.1 | AC14: 105 | AD14: 105.5 | AE14: 102.1 | AF14: 104.8 | AG14: 107.2 | AH14: =SUM(X14:AF14,G14:V14) -> 2699.571 | AI14: =SUM(AF14,AE14,AD14,AC14) -> 417.4 | AJ14: =SUM(V14,U14) -> 216.7 | AK14: =SUM(Z14,X14) -> 246.07097 | AL14: =SUM(G14:T14) -> 1502.1 | AM14: =AVERAGE(AF14,AE14,AD14,AC14) -> 104.35 | AN14: =AVERAGE(X14,Z14) -> 123.03548 | AO14: 107.29286
A15: Urban | B15: 2013 | C15: May | D15: =TEXT(DATE(B15, MONTH(1&C15), 1), "mmm-yy") -> May-13 | E15: 41395 | F15: Pre covid | G15: 115.4 | H15: 114.2 | I15: 102.7 | J15: 105.5 | K15: 101.5 | L15: 110.6 | M15: 123.7 | N15: 105.2 | O15: 101.9 | P15: 105 | Q15: 109.1 | R15: 111.3 | S15: 111.1 | T15: 109.8 | U15: 108.5 | V15: 106.7 | W15: 108.3 | X15: 100.5 | Y15: 107.2 | Z15: 107.1 | AA15: 106.2 | AB15: 103.9 | AC15: 104.6 | AD15: 105.7 | AE15: 102.6 | AF15: 104.9 | AG15: 106.6 | AH15: =SUM(X15:AF15,G15:V15) -> 2684.9 | AI15: =SUM(AF15,AE15,AD15,AC15) -> 417.8 | AJ15: =SUM(V15,U15) -> 215.2 | AK15: =SUM(Z15,X15) -> 207.6 | AL15: =SUM(G15:T15) -> 1527 | AM15: =AVERAGE(AF15,AE15,AD15,AC15) -> 104.45 | AN15: =AVERAGE(X15,Z15) -> 103.8 | AO15: 109.07143
A16: Rural+Urban | B16: 2013 | C16: May | D16: =TEXT(DATE(B16, MONTH(1&C16), 1), "mmm-yy") -> May-13 | E16: 41395 | F16: Pre covid | G16: 112.3 | H16: 111.3 | I16: 104.7 | J16: 106.8 | K16: 103.9 | L16: 109.3 | M16: 112.9 | N16: 105.8 | O16: 103.1 | P16: 104.3 | Q16: 108.1 | R16: 110.5 | S16: 109.2 | T16: 108.6 | U16: 108.7 | V16: 107.4 | W16: 108.5 | X16: 100.5 | Y16: 107.4 | Z16: 106.9 | AA16: 105.9 | AB16: 104 | AC16: 104.8 | AD16: 105.6 | AE16: 102.3 | AF16: 104.8 | AG16: 106.9 | AH16: =SUM(X16:AF16,G16:V16) -> 2669.1 | AI16: =SUM(AF16,AE16,AD16,AC16) -> 417.5 | AJ16: =SUM(V16,U16) -> 216.1 | AK16: =SUM(Z16,X16) -> 207.4 | AL16: =SUM(G16:T16) -> 1510.8 | AM16: =AVERAGE(AF16,AE16,AD16,AC16) -> 104.375 | AN16: =AVERAGE(X16,Z16) -> 103.7 | AO16: 107.91429
A17: Rural | B17: 2013 | C17: June | D17: =TEXT(DATE(B17, MONTH(1&C17), 1), "mmm-yy") -> Jun-13 | E17: 41426 | F17: Pre covid | G17: 112.3 | H17: 112.1 | I17: 108.1 | J17: 108.3 | K17: 105.9 | L17: 109.2 | M17: 118 | N17: 106.8 | O17: 104.1 | P17: 105.4 | Q17: 108.2 | R17: 111 | S17: 110.6 | T17: 109 | U17: 109.7 | V17: 108.8 | W17: 109.5 | X17: ='Handle missing value sheet only'!$C$1 -> 139.27097 | Y17: 108.5 | Z17: 107.5 | AA17: 106.3 | AB17: 105 | AC17: 105.6 | AD17: 106.5 | AE17: 102.5 | AF17: 105.5 | AG17: 108.9 | AH17: =SUM(X17:AF17,G17:V17) -> 2734.171 | AI17: =SUM(AF17,AE17,AD17,AC17) -> 420.1 | AJ17: =SUM(V17,U17) -> 218.5 | AK17: =SUM(Z17,X17) -> 246.77097 | AL17: =SUM(G17:T17) -> 1529 | AM17: =AVERAGE(AF17,AE17,AD17,AC17) -> 105.025 | AN17: =AVERAGE(X17,Z17) -> 123.38548 | AO17: 109.21429
A18: Urban | B18: 2013 | C18: June | D18: =TEXT(DATE(B18, MONTH(1&C18), 1), "mmm-yy") -> Jun-13 | E18: 41426 | F18: Pre covid | G18: 117 | H18: 120.1 | I18: 112.5 | J18: 107.3 | K18: 101.3 | L18: 112.4 | M18: 143.6 | N18: 105.4 | O18: 101.4 | P18: 106.4 | Q18: 110 | R18: 112.2 | S18: 115 | T18: 110.9 | U18: 109.2 | V18: 107.2 | W18: 108.9 | X18: 106.6 | Y18: 108 | Z18: 107.7 | AA18: 106.5 | AB18: 105.2 | AC18: 105.2 | AD18: 108.1 | AE18: 103.3 | AF18: 106.1 | AG18: 109.7 | AH18: =SUM(X18:AF18,G18:V18) -> 2748.6 | AI18: =SUM(AF18,AE18,AD18,AC18) -> 422.7 | AJ18: =SUM(V18,U18) -> 216.4 | AK18: =SUM(Z18,X18) -> 214.3 | AL18: =SUM(G18:T18) -> 1575.5 | AM18: =AVERAGE(AF18,AE18,AD18,AC18) -> 105.675 | AN18: =AVERAGE(X18,Z18) -> 107.15 | AO18: 112.53571
A19: Rural+Urban | B19: 2013 | C19: June | D19: =TEXT(DATE(B19, MONTH(1&C19), 1), "mmm-yy") -> Jun-13 | E19: 41426 | F19: Pre covid | G19: 113.8 | H19: 114.9 | I19: 109.8 | J19: 107.9 | K19: 104.2 | L19: 110.7 | M19: 126.7 | N19: 106.3 | O19: 103.2 | P19: 105.7 | Q19: 109 | R19: 111.6 | S19: 112.2 | T19: 109.5 | U19: 109.5 | V19: 108.1 | W19: 109.3 | X19: 106.6 | Y19: 108.3 | Z19: 107.6 | AA19: 106.4 | AB19: 105.1 | AC19: 105.4 | AD19: 107.4 | AE19: 102.8 | AF19: 105.8 | AG19: 109.3 | AH19: =SUM(X19:AF19,G19:V19) -> 2718.5 | AI19: =SUM(AF19,AE19,AD19,AC19) -> 421.4 | AJ19: =SUM(V19,U19) -> 217.6 | AK19: =SUM(Z19,X19) -> 214.2 | AL19: =SUM(G19:T19) -> 1545.5 | AM19: =AVERAGE(AF19,AE19,AD19,AC19) -> 105.35 | AN19: =AVERAGE(X19,Z19) -> 107.1 | AO19: 110.39286
A20: Rural | B20: 2013 | C20: July | D20: =TEXT(DATE(B20, MONTH(1&C20), 1), "mmm-yy") -> Jul-13 | E20: 41456 | F20: Pre covid | G20: 113.4 | H20: 114.9 | I20: 110.5 | J20: 109.3 | K20: 106.2 | L20: 110.3 | M20: 129.2 | N20: 107.1 | O20: 104.3 | P20: 106.4 | Q20: 109.1 | R20: 112.1 | S20: 113.1 | T20: 109.8 | U20: 110.5 | V20: 109.5 | W20: 110.3 | X20: ='Handle missing value sheet only'!$C$1 -> 139.27097 | Y20: 109.5 | Z20: 108.3 | AA20: 106.9 | AB20: 106.8 | AC20: 106.4 | AD20: 107.8 | AE20: 102.5 | AF20: 106.5 | AG20: 110.7 | AH20: =SUM(X20:AF20,G20:V20) -> 2769.671 | AI20: =SUM(AF20,AE20,AD20,AC20) -> 423.2 | AJ20: =SUM(V20,U20) -> 220 | AK20: =SUM(Z20,X20) -> 247.57097 | AL20: =SUM(G20:T20) -> 1555.7 | AM20: =AVERAGE(AF20,AE20,AD20,AC20) -> 105.8 | AN20: =AVERAGE(X20,Z20) -> 123.78548 | AO20: 111.12143
A21: Urban | B21: 2013 | C21: July | D21: =TEXT(DATE(B21, MONTH(1&C21), 1), "mmm-yy") -> Jul-13 | E21: 41456 | F21: Pre covid | G21: 117.8 | H21: 119.2 | I21: 114 | J21: 108.3 | K21: 101.1 | L21: 113.2 | M21: 160.9 | N21: 105.1 | O21: 101.3 | P21: 107.5 | Q21: 110.4 | R21: 113.1 | S21: 117.5 | T21: 111.7 | U21: 109.8 | V21: 107.8 | W21: 109.5 | X21: 107.7 | Y21: 108.6 | Z21: 108.1 | AA21: 107.1 | AB21: 107.3 | AC21: 105.9 | AD21: 110.1 | AE21: 103.2 | AF21: 107.3 | AG21: 111.4 | AH21: =SUM(X21:AF21,G21:V21) -> 2784 | AI21: =SUM(AF21,AE21,AD21,AC21) -> 426.5 | AJ21: =SUM(V21,U21) -> 217.6 | AK21: =SUM(Z21,X21) -> 215.8 | AL21: =SUM(G21:T21) -> 1601.1 | AM21: =AVERAGE(AF21,AE21,AD21,AC21) -> 106.625 | AN21: =AVERAGE(X21,Z21) -> 107.9 | AO21: 114.36429
A22: Rural+Urban | B22: 2013 | C22: July | D22: =TEXT(DATE(B22, MONTH(1&C22), 1), "mmm-yy") -> Jul-13 | E22: 41456 | F22: Pre covid | G22: 114.8 | H22: 116.4 | I22: 111.9 | J22: 108.9 | K22: 104.3 | L22: 111.7 | M22: 140 | N22: 106.4 | O22: 103.3 | P22: 106.8 | Q22: 109.6 | R22: 112.6 | S22: 114.7 | T22: 110.3 | U22: 110.2 | V22: 108.8 | W22: 110 | X22: 107.7 | Y22: 109.2 | Z22: 108.2 | AA22: 107 | AB22: 107.1 | AC22: 106.1 | AD22: 109.1 | AE22: 102.8 | AF22: 106.9 | AG22: 111 | AH22: =SUM(X22:AF22,G22:V22) -> 2754.8 | AI22: =SUM(AF22,AE22,AD22,AC22) -> 424.9 | AJ22: =SUM(V22,U22) -> 219 | AK22: =SUM(Z22,X22) -> 215.9 | AL22: =SUM(G22:T22) -> 1571.7 | AM22: =AVERAGE(AF22,AE22,AD22,AC22) -> 106.225 | AN22: =AVERAGE(X22,Z22) -> 107.95 | AO22: 112.26429
A23: Rural | B23: 2013 | C23: August | D23: =TEXT(DATE(B23, MONTH(1&C23), 1), "mmm-yy") -> Aug-13 | E23: 41487 | F23: Pre covid | G23: 114.3 | H23: 115.4 | I23: 111.1 | J23: 110 | K23: 106.4 | L23: 110.8 | M23: 138.9 | N23: 107.4 | O23: 104.1 | P23: 106.9 | Q23: 109.7 | R23: 112.6 | S23: 114.9 | T23: 110.7 | U23: 111.3 | V23: 110.2 | W23: 111.1 | X23: ='Handle missing value sheet only'!$C$1 -> 139.27097 | Y23: 109.9 | Z23: 108.7 | AA23: 107.5 | AB23: 107.8 | AC23: 106.8 | AD23: 108.7 | AE23: 105 | AF23: 107.5 | AG23: 112.1 | AH23: =SUM(X23:AF23,G23:V23) -> 2795.871 | AI23: =SUM(AF23,AE23,AD23,AC23) -> 428 | AJ23: =SUM(V23,U23) -> 221.5 | AK23: =SUM(Z23,X23) -> 247.97097 | AL23: =SUM(G23:T23) -> 1573.2 | AM23: =AVERAGE(AF23,AE23,AD23,AC23) -> 107 | AN23: =AVERAGE(X23,Z23) -> 123.98548 | AO23: 112.37143
A24: Urban | B24: 2013 | C24: August | D24: =TEXT(DATE(B24, MONTH(1&C24), 1), "mmm-yy") -> Aug-13 | E24: 41487 | F24: Pre covid | G24: 118.3 | H24: 120.4 | I24: 112.7 | J24: 108.9 | K24: 101.1 | L24: 108.7 | M24: 177 | N24: 104.7 | O24: 101 | P24: 108.5 | Q24: 110.9 | R24: 114.3 | S24: 119.6 | T24: 112.4 | U24: 110.6 | V24: 108.3 | W24: 110.2 | X24: 108.9 | Y24: 109.3 | Z24: 108.7 | AA24: 107.6 | AB24: 108.1 | AC24: 106.5 | AD24: 110.8 | AE24: 106 | AF24: 108.3 | AG24: 112.7 | AH24: =SUM(X24:AF24,G24:V24) -> 2811.6 | AI24: =SUM(AF24,AE24,AD24,AC24) -> 431.6 | AJ24: =SUM(V24,U24) -> 218.9 | AK24: =SUM(Z24,X24) -> 217.6 | AL24: =SUM(G24:T24) -> 1618.5 | AM24: =AVERAGE(AF24,AE24,AD24,AC24) -> 107.9 | AN24: =AVERAGE(X24,Z24) -> 108.8 | AO24: 115.60714
A25: Rural+Urban | B25: 2013 | C25: August | D25: =TEXT(DATE(B25, MONTH(1&C25), 1), "mmm-yy") -> Aug-13 | E25: 41487 | F25: Pre covid | G25: 115.6 | H25: 117.2 | I25: 111.7 | J25: 109.6 | K25: 104.5 | L25: 109.8 | M25: 151.8 | N25: 106.5 | O25: 103.1 | P25: 107.4 | Q25: 110.2 | R25: 113.4 | S25: 116.6 | T25: 111.2 | U25: 111 | V25: 109.4 | W25: 110.7 | X25: 108.9 | Y25: 109.7 | Z25: 108.7 | AA25: 107.5 | AB25: 108 | AC25: 106.6 | AD25: 109.9 | AE25: 105.4 | AF25: 107.9 | AG25: 112.4 | AH25: =SUM(X25:AF25,G25:V25) -> 2781.6 | AI25: =SUM(AF25,AE25,AD25,AC25) -> 429.8 | AJ25: =SUM(V25,U25) -> 220.4 | AK25: =SUM(Z25,X25) -> 217.6 | AL25: =SUM(G25:T25) -> 1588.6 | AM25: =AVERAGE(AF25,AE25,AD25,AC25) -> 107.45 | AN25: =AVERAGE(X25,Z25) -> 108.8 | AO25: 113.47143
A26: Rural | B26: 2013 | C26: September | D26: =TEXT(DATE(B26, MONTH(1&C26), 1), "mmm-yy") -> Sep-13 | E26: 41518 | F26: Pre covid | G26: 115.4 | H26: 115.7 | I26: 111.7 | J26: 111 | K26: 107.4 | L26: 110.9 | M26: 154 | N26: 108.1 | O26: 104.2 | P26: 107.9 | Q26: 110.4 | R26: 114 | S26: 117.8 | T26: 111.7 | U26: 112.7 | V26: 111.4 | W26: 112.5 | X26: ='Handle missing value sheet only'!$C$1 -> 139.27097 | Y26: 111.1 | Z26: 109.6 | AA26: 108.3 | AB26: 109.3 | AC26: 107.7 | AD26: 109.8 | AE26: 106.7 | AF26: 108.7 | AG26: 114.2 | AH26: =SUM(X26:AF26,G26:V26) -> 2834.771 | AI26: =SUM(AF26,AE26,AD26,AC26) -> 432.9 | AJ26: =SUM(V26,U26) -> 224.1 | AK26: =SUM(Z26,X26) -> 248.87097 | AL26: =SUM(G26:T26) -> 1600.2 | AM26: =AVERAGE(AF26,AE26,AD26,AC26) -> 108.225 | AN26: =AVERAGE(X26,Z26) -> 124.43548 | AO26: 114.3
A27: Urban | B27: 2013 | C27: September | D27: =TEXT(DATE(B27, MONTH(1&C27), 1), "mmm-yy") -> Sep-13 | E27: 41518 | F27: Pre covid | G27: 118.6 | H27: 119.1 | I27: 113.2 | J27: 109.6 | K27: 101.7 | L27: 103.2 | M27: 174.3 | N27: 105.1 | O27: 100.8 | P27: 109.1 | Q27: 111.1 | R27: 115.4 | S27: 119.2 | T27: 112.9 | U27: 111.4 | V27: 109 | W27: 111.1 | X27: 109.7 | Y27: 109.5 | Z27: 109.6 | AA27: 107.9 | AB27: 110.4 | AC27: 107.4 | AD27: 111.2 | AE27: 106.9 | AF27: 109.4 | AG27: 113.2 | AH27: =SUM(X27:AF27,G27:V27) -> 2815.7 | AI27: =SUM(AF27,AE27,AD27,AC27) -> 434.9 | AJ27: =SUM(V27,U27) -> 220.4 | AK27: =SUM(Z27,X27) -> 219.3 | AL27: =SUM(G27:T27) -> 1613.3 | AM27: =AVERAGE(AF27,AE27,AD27,AC27) -> 108.725 | AN27: =AVERAGE(X27,Z27) -> 109.65 | AO27: 115.23571
A28: Rural+Urban | B28: 2013 | C28: September | D28: =TEXT(DATE(B28, MONTH(1&C28), 1), "mmm-yy") -> Sep-13 | E28: 41518 | F28: Pre covid | G28: 116.4 | H28: 116.9 | I28: 112.3 | J28: 110.5 | K28: 105.3 | L28: 107.3 | M28: 160.9 | N28: 107.1 | O28: 103.1 | P28: 108.3 | Q28: 110.7 | R28: 114.6 | S28: 118.3 | T28: 112 | U28: 112.2 | V28: 110.4 | W28: 111.9 | X28: 109.7 | Y28: 110.5 | Z28: 109.6 | AA28: 108.1 | AB28: 109.9 | AC28: 107.5 | AD28: 110.6 | AE28: 106.8 | AF28: 109 | AG28: 113.7 | AH28: =SUM(X28:AF28,G28:V28) -> 2808 | AI28: =SUM(AF28,AE28,AD28,AC28) -> 433.9 | AJ28: =SUM(V28,U28) -> 222.6 | AK28: =SUM(Z28,X28) -> 219.3 | AL28: =SUM(G28:T28) -> 1603.7 | AM28: =AVERAGE(AF28,AE28,AD28,AC28) -> 108.475 | AN28: =AVERAGE(X28,Z28) -> 109.65 | AO28: 114.55
A29: Rural | B29: 2013 | C29: October | D29: =TEXT(DATE(B29, MONTH(1&C29), 1), "mmm-yy") -> Oct-13 | E29: 41548 | F29: Pre covid | G29: 116.3 | H29: 115.4 | I29: 112.6 | J29: 111.7 | K29: 107.7 | L29: 113.2 | M29: 164.9 | N29: 108.3 | O29: 103.9 | P29: 108.2 | Q29: 111.1 | R29: 114.9 | S29: 119.8 | T29: 112.2 | U29: 113.6 | V29: 112.3 | W29: 113.4 | X29: ='Handle missing value sheet only'!$C$1 -> 139.27097 | Y29: 111.6 | Z29: 110.4 | AA29: 108.9 | AB29: 109.3 | AC29: 108.3 | AD29: 110.2 | AE29: 107.5 | AF29: 109.1 | AG29: 115.5 | AH29: =SUM(X29:AF29,G29:V29) -> 2860.671 | AI29: =SUM(AF29,AE29,AD29,AC29) -> 435.1 | AJ29: =SUM(V29,U29) -> 225.9 | AK29: =SUM(Z29,X29) -> 249.67097 | AL29: =SUM(G29:T29) -> 1620.2 | AM29: =AVERAGE(AF29,AE29,AD29,AC29) -> 108.775 | AN29: =AVERAGE(X29,Z29) -> 124.83548 | AO29: 115.72857
A30: Urban | B30: 2013 | C30: October | D30: =TEXT(DATE(B30, MONTH(1&C30), 1), "mmm-yy") -> Oct-13 | E30: 41548 | F30: Pre covid | G30: 118.9 | H30: 118.1 | I30: 114.5 | J30: 110.4 | K30: 102.3 | L30: 106.2 | M30: 183.5 | N30: 105.3 | O30: 100.2 | P30: 109.6 | Q30: 111.4 | R30: 116 | S30: 120.8 | T30: 113.5 | U30: 112.5 | V30: 109.7 | W30: 112 | X30: 110.5 | Y30: 109.7 | Z30: 110.2 | AA30: 108.2 | AB30: 109.7 | AC30: 108 | AD30: 111.3 | AE30: 107.3 | AF30: 109.4 | AG30: 114 | AH30: =SUM(X30:AF30,G30:V30) -> 2837.2 | AI30: =SUM(AF30,AE30,AD30,AC30) -> 436 | AJ30: =SUM(V30,U30) -> 222.2 | AK30: =SUM(Z30,X30) -> 220.7 | AL30: =SUM(G30:T30) -> 1630.7 | AM30: =AVERAGE(AF30,AE30,AD30,AC30) -> 109 | AN30: =AVERAGE(X30,Z30) -> 110.35 | AO30: 116.47857
A31: Rural+Urban | B31: 2013 | C31: October | D31: =TEXT(DATE(B31, MONTH(1&C31), 1), "mmm-yy") -> Oct-13 | E31: 41548 | F31: Pre covid | G31: 117.1 | H31: 116.3 | I31: 113.3 | J31: 111.2 | K31: 105.7 | L31: 109.9 | M31: 171.2 | N31: 107.3 | O31: 102.7 | P31: 108.7 | Q31: 111.2 | R31: 115.4 | S31: 120.2 | T31: 112.5 | U31: 113.2 | V31: 111.2 | W31: 112.8 | X31: 110.5 | Y31: 110.9 | Z31: 110.3 | AA31: 108.6 | AB31: 109.5 | AC31: 108.1 | AD31: 110.8 | AE31: 107.4 | AF31: 109.2 | AG31: 114.8 | AH31: =SUM(X31:AF31,G31:V31) -> 2832.4 | AI31: =SUM(AF31,AE31,AD31,AC31) -> 435.5 | AJ31: =SUM(V31,U31) -> 224.4 | AK31: =SUM(Z31,X31) -> 220.8 | AL31: =SUM(G31:T31) -> 1622.7 | AM31: =AVERAGE(AF31,AE31,AD31,AC31) -> 108.875 | AN31: =AVERAGE(X31,Z31) -> 110.4 | AO31: 115.90714
A32: Rural | B32: 2013 | C32: November | D32: =TEXT(DATE(B32, MONTH(1&C32), 1), "mmm-yy") -> Nov-13 | E32: 41579 | F32: Pre covid | G32: 117.3 | H32: 114.9 | I32: 116.2 | J32: 112.8 | K32: 108.9 | L32: 116.6 | M32: 178.1 | N32: 109.1 | O32: 103.6 | P32: 109 | Q32: 111.8 | R32: 116 | S32: 122.5 | T32: 112.8 | U32: 114.6 | V32: 113.1 | W32: 114.4 | X32: ='Handle missing value sheet only'!$C$1 -> 139.27097 | Y32: 112.6 | Z32: 111.3 | AA32: 109.7 | AB32: 109.6 | AC32: 108.7 | AD32: 111 | AE32: 108.2 | AF32: 109.8 | AG32: 117.4 | AH32: =SUM(X32:AF32,G32:V32) -> 2897.471 | AI32: =SUM(AF32,AE32,AD32,AC32) -> 437.7 | AJ32: =SUM(V32,U32) -> 227.7 | AK32: =SUM(Z32,X32) -> 250.57097 | AL32: =SUM(G32:T32) -> 1649.6 | AM32: =AVERAGE(AF32,AE32,AD32,AC32) -> 109.425 | AN32: =AVERAGE(X32,Z32) -> 125.28548 | AO32: 117.82857
A33: Urban | B33: 2013 | C33: November | D33: =TEXT(DATE(B33, MONTH(1&C33), 1), "mmm-yy") -> Nov-13 | E33: 41579 | F33: Pre covid | G33: 119.8 | H33: 116.3 | I33: 122.6 | J33: 112 | K33: 103.2 | L33: 110 | M33: 192.8 | N33: 106.3 | O33: 99.5 | P33: 110.3 | Q33: 111.8 | R33: 117.1 | S33: 122.9 | T33: 114.1 | U33: 113.5 | V33: 110.3 | W33: 113 | X33: 111.1 | Y33: 110 | Z33: 110.9 | AA33: 108.6 | AB33: 109.5 | AC33: 108.5 | AD33: 111.3 | AE33: 107.9 | AF33: 109.6 | AG33: 115 | AH33: =SUM(X33:AF33,G33:V33) -> 2869.9 | AI33: =SUM(AF33,AE33,AD33,AC33) -> 437.3 | AJ33: =SUM(V33,U33) -> 223.8 | AK33: =SUM(Z33,X33) -> 222 | AL33: =SUM(G33:T33) -> 1658.7 | AM33: =AVERAGE(AF33,AE33,AD33,AC33) -> 109.325 | AN33: =AVERAGE(X33,Z33) -> 111 | AO33: 118.47857
A34: Rural+Urban | B34: 2013 | C34: November | D34: =TEXT(DATE(B34, MONTH(1&C34), 1), "mmm-yy") -> Nov-13 | E34: 41579 | F34: Pre covid | G34: 118.1 | H34: 115.4 | I34: 118.7 | J34: 112.5 | K34: 106.8 | L34: 113.5 | M34: 183.1 | N34: 108.2 | O34: 102.2 | P34: 109.4 | Q34: 111.8 | R34: 116.5 | S34: 122.6 | T34: 113.1 | U34: 114.2 | V34: 111.9 | W34: 113.8 | X34: 111.1 | Y34: 111.6 | Z34: 111.1 | AA34: 109.3 | AB34: 109.5 | AC34: 108.6 | AD34: 111.2 | AE34: 108.1 | AF34: 109.7 | AG34: 116.3 | AH34: =SUM(X34:AF34,G34:V34) -> 2868.2 | AI34: =SUM(AF34,AE34,AD34,AC34) -> 437.6 | AJ34: =SUM(V34,U34) -> 226.1 | AK34: =SUM(Z34,X34) -> 222.2 | AL34: =SUM(G34:T34) -> 1651.9 | AM34: =AVERAGE(AF34,AE34,AD34,AC34) -> 109.4 | AN34: =AVERAGE(X34,Z34) -> 111.1 | AO34: 117.99286
A35: Rural | B35: 2013 | C35: December | D35: =TEXT(DATE(B35, MONTH(1&C35), 1), "mmm-yy") -> Dec-13 | E35: 41609 | F35: Pre covid | G35: 118.4 | H35: 115.9 | I35: 120.4 | J35: 113.8 | K35: 109.5 | L35: 115.5 | M35: 145.7 | N35: 109.5 | O35: 102.9 | P35: 109.8 | Q35: 112.1 | R35: 116.8 | S35: 118.7 | T35: 113.6 | U35: 115.8 | V35: 114 | W35: 115.5 | X35: ='Handle missing value sheet only'!$C$1 -> 139.27097 | Y35: 112.8 | Z35: 112.1 | AA35: 110.1 | AB35: 109.9 | AC35: 109.2 | AD35: 111.6 | AE35: 108.1 | AF35: 110.1 | AG35: 115.5 | AH35: =SUM(X35:AF35,G35:V35) -> 2875.571 | AI35: =SUM(AF35,AE35,AD35,AC35) -> 439 | AJ35: =SUM(V35,U35) -> 229.8 | AK35: =SUM(Z35,X35) -> 251.37097 | AL35: =SUM(G35:T35) -> 1622.6 | AM35: =AVERAGE(AF35,AE35,AD35,AC35) -> 109.75 | AN35: =AVERAGE(X35,Z35) -> 125.68548 | AO35: 115.9
A36: Urban | B36: 2013 | C36: December | D36: =TEXT(DATE(B36, MONTH(1&C36), 1), "mmm-yy") -> Dec-13 | E36: 41609 | F36: Pre covid | G36: 120.5 | H36: 118.1 | I36: 128.5 | J36: 112.8 | K36: 103.4 | L36: 110.7 | M36: 144.8 | N36: 107.1 | O36: 98.6 | P36: 111.9 | Q36: 112.1 | R36: 118.1 | S36: 117.8 | T36: 115 | U36: 114.2 | V36: 110.9 | W36: 113.7 | X36: 110.7 | Y36: 110.4 | Z36: 111.3 | AA36: 109 | AB36: 109.7 | AC36: 108.9 | AD36: 111.4 | AE36: 107.7 | AF36: 109.8 | AG36: 113.3 | AH36: =SUM(X36:AF36,G36:V36) -> 2833.4 | AI36: =SUM(AF36,AE36,AD36,AC36) -> 437.8 | AJ36: =SUM(V36,U36) -> 225.1 | AK36: =SUM(Z36,X36) -> 222 | AL36: =SUM(G36:T36) -> 1619.4 | AM36: =AVERAGE(AF36,AE36,AD36,AC36) -> 109.45 | AN36: =AVERAGE(X36,Z36) -> 111 | AO36: 115.67143
A37: Rural+Urban | B37: 2013 | C37: December | D37: =TEXT(DATE(B37, MONTH(1&C37), 1), "mmm-yy") -> Dec-13 | E37: 41609 | F37: Pre covid | G37: 119.1 | H37: 116.7 | I37: 123.5 | J37: 113.4 | K37: 107.3 | L37: 113.3 | M37: 145.4 | N37: 108.7 | O37: 101.5 | P37: 110.5 | Q37: 112.1 | R37: 117.4 | S37: 118.4 | T37: 114 | U37: 115.2 | V37: 112.7 | W37: 114.8 | X37: 110.7 | Y37: 111.9 | Z37: 111.7 | AA37: 109.7 | AB37: 109.8 | AC37: 109 | AD37: 111.5 | AE37: 107.9 | AF37: 110 | AG37: 114.5 | AH37: =SUM(X37:AF37,G37:V37) -> 2841.4 | AI37: =SUM(AF37,AE37,AD37,AC37) -> 438.4 | AJ37: =SUM(V37,U37) -> 227.9 | AK37: =SUM(Z37,X37) -> 222.4 | AL37: =SUM(G37:T37) -> 1621.3 | AM37: =AVERAGE(AF37,AE37,AD37,AC37) -> 109.6 | AN37: =AVERAGE(X37,Z37) -> 111.2 | AO37: 115.80714
A38: Rural | B38: 2014 | C38: January | D38: =TEXT(DATE(B38, MONTH(1&C38), 1), "mmm-yy") -> Jan-14 | E38: 41640 | F38: Pre covid | G38: 118.9 | H38: 117.1 | I38: 120.5 | J38: 114.4 | K38: 109 | L38: 115.5 | M38: 123.9 | N38: 109.6 | O38: 101.8 | P38: 110.2 | Q38: 112.4 | R38: 117.3 | S38: 116 | T38: 114 | U38: 116.5 | V38: 114.5 | W38: 116.2 | X38: ='Handle missing value sheet only'!$C$1 -> 139.27097 | Y38: 113 | Z38: 112.6 | AA38: 110.6 | AB38: 110.5 | AC38: 109.6 | AD38: 111.8 | AE38: 108.3 | AF38: 110.6 | AG38: 114.2 | AH38: =SUM(X38:AF38,G38:V38) -> 2857.871 | AI38: =SUM(AF38,AE38,AD38,AC38) -> 440.3 | AJ38: =SUM(V38,U38) -> 231 | AK38: =SUM(Z38,X38) -> 251.87097 | AL38: =SUM(G38:T38) -> 1600.6 | AM38: =AVERAGE(AF38,AE38,AD38,AC38) -> 110.075 | AN38: =AVERAGE(X38,Z38) -> 125.93548 | AO38: 114.32857
A39: Urban | B39: 2014 | C39: January | D39: =TEXT(DATE(B39, MONTH(1&C39), 1), "mmm-yy") -> Jan-14 | E39: 41640 | F39: Pre covid | G39: 121.2 | H39: 122 | I39: 129.9 | J39: 113.6 | K39: 102.9 | L39: 112.1 | M39: 118.9 | N39: 107.5 | O39: 96.9 | P39: 112.7 | Q39: 112.1 | R39: 119 | S39: 115.5 | T39: 115.7 | U39: 114.8 | V39: 111.3 | W39: 114.3 | X39: 111.6 | Y39: 111 | Z39: 111.9 | AA39: 109.7 | AB39: 110.8 | AC39: 109.8 | AD39: 111.5 | AE39: 108 | AF39: 110.5 | AG39: 112.9 | AH39: =SUM(X39:AF39,G39:V39) -> 2820.9 | AI39: =SUM(AF39,AE39,AD39,AC39) -> 439.8 | AJ39: =SUM(V39,U39) -> 226.1 | AK39: =SUM(Z39,X39) -> 223.5 | AL39: =SUM(G39:T39) -> 1600 | AM39: =AVERAGE(AF39,AE39,AD39,AC39) -> 109.95 | AN39: =AVERAGE(X39,Z39) -> 111.75 | AO39: 114.28571
A40: Rural+Urban | B40: 2014 | C40: January | D40: =TEXT(DATE(B40, MONTH(1&C40), 1), "mmm-yy") -> Jan-14 | E40: 41640 | F40: Pre covid | G40: 119.6 | H40: 118.8 | I40: 124.1 | J40: 114.1 | K40: 106.8 | L40: 113.9 | M40: 122.2 | N40: 108.9 | O40: 100.2 | P40: 111 | Q40: 112.3 | R40: 118.1 | S40: 115.8 | T40: 114.5 | U40: 115.8 | V40: 113.2 | W40: 115.4 | X40: 111.6 | Y40: 112.2 | Z40: 112.3 | AA40: 110.3 | AB40: 110.7 | AC40: 109.7 | AD40: 111.6 | AE40: 108.2 | AF40: 110.6 | AG40: 113.6 | AH40: =SUM(X40:AF40,G40:V40) -> 2826.5 | AI40: =SUM(AF40,AE40,AD40,AC40) -> 440.1 | AJ40: =SUM(V40,U40) -> 229 | AK40: =SUM(Z40,X40) -> 223.9 | AL40: =SUM(G40:T40) -> 1600.3 | AM40: =AVERAGE(AF40,AE40,AD40,AC40) -> 110.025 | AN40: =AVERAGE(X40,Z40) -> 111.95 | AO40: 114.30714
...

Sheet Problem statement 
A1: Problem 1
O4: Impact of Global Oil Price Fluctuations: A strong positive correlation is observed between imported crude oil prices and prices in sub catagories
A5: 1. Based on the latest month’s data, identify the contribution of different broader categories (food, energy, transportation, education, etc.) towards the CPI basket. Broader categories (buckets) can be created by combining similar categories into one bucket; Ex.: Meals, Beverages, Cereals, can be clubbed to create “Food” category, etc.
A7: Which broader category has the highest contribution towards CPI calculation
A9: Contribution is calculated by evaluating the underlying index values for broader category and should add to 100% when contribution from different broader categories are added.
A10: Problem 2
A14: 2. A trend of Y-o-Y increase in CPI (rural + urban) inflation starting 2017 for the entire basket of products combined.
A16: ◦ Create a graph depicting the growth rate Y-o-Y and identify the year with highest inflation rate
A18: ◦ Highlight the reason why the year has the highest inflation (based on research).
A19: Problem 3
A23: 3. With India's retail inflation reaching a 3-month high of 5.55% in November 2023, largely due to a sharp rise in food prices. Analyze the following for 12 months ending May'23
A25: Investigate trends in the prices of broader food bucket category and evaluate month-on-month changes. Highlight month with highest and lowest food inflation
A27: Identify the absolute changes in inflation over the same 12 months period and identify the biggest individual category contributor (only within broader food category) towards inflation
A28: Problem 4
... A44: Identify trends in oil price change with change in inflation prices of all the categories and identify category whose inflation prices strongly changes with fluctuations in imported oil price (Hint: you can use =CORREL function).

Sheet Data Dictionary 
A1: Glossary | C1: Remark
B2: include of sum this
A3: Food expense | B3: Cereals and products
B4: Meat and fish
B5: Egg
B6: Milk and products
B7: Oils and fats
B8: Fruits
B9: Vegetables
B10: Pulses and products
B11: Sugar and Confectionery
B12: Spices
B13: Non-alcoholic beverages
B14: Prepared meals, snacks, sweets etc.
B15: Food and beverages
B16: Pan, tobacco and intoxicants
A18: Housing expences | B18: include sum of
B19: Housing | C19: handle missing value
B20: Household goods and services
A22: clothing | B22: Include only
B23: Clothing and footwear
A25: fuel and light | B25: sum of
B26: Fuel and light | C26: handle blanks
A28: Health | B28: include
B29: Health
A31: Transport and communication | B31: include of
B32: Transport and communication
A34: Others | B34: sum of
B35: Recreation and amusement
B36: Personal care and effects
B37: Miscellaneous
B38: Education
A39: General Index | B39: avg of total expences

Sheet Handle missing value sheet only
A1: Housing | B1: mean | C1: =AVERAGE(A2:A373) -> 139.27097
A2: 139.3 | B2: median | C2: =MEDIAN(A2:A373) -> 139.3
A3: 100.3 | B3: standaed | C3: =STDEV(A2:A373) -> 17.19329
A4: 100.3
A5: 139.3
A6: 100.4
A7: 100.4
A8: 139.3
A9: 100.4
A10: 100.4
A11: 139.3
A12: 100.5
A13: 100.5
A14: 139.3
A15: 100.5
... A373: 175.6

Sheet Solution 1
A1: Sector | B1: Year | C1: Month | D1: date | E1: Pre/Post Covid | F1: Cereals and products | G1: Meat and fish | H1: Egg | I1: Milk and products | J1: Oils and fats | K1: Fruits | L1: Vegetables | M1: Pulses and products | N1: Sugar and Confectionery | O1: Spices | P1: Non-alcoholic beverages | Q1: Prepared meals, snacks, sweets etc. | R1: Food and beverages | S1: Pan, tobacco and intoxicants | T1: Clothing | U1: Footwear | V1: Clothing and footwear | W1: Housing | X1: Fuel and light | Y1: Household goods and services | Z1: Health | AA1: Transport and communication | AB1: Recreation and amusement | AC1: Education | AD1: Personal care and effects | AE1: Miscellaneous | AF1: General index | AG1: Total Expences | AH1: sum of others | AI1: sum of clothing | AJ1: Sum Housing Exepences | AK1: Sum of food expences | AL1: Average Other Expences | AM1: Average Housing Expences | AN1: Average Food Expences
A2: Rural | B2: 2023 | C2: May | D2: 45047 | E2: Post covid | F2: 173.2 | G2: 211.5 | H2: 171 | I2: 179.6 | J2: 173.3 | K2: 169 | L2: 148.7 | M2: 174.9 | N2: 121.9 | O2: 221 | P2: 178.7 | Q2: 191.1 | R2: 176.8 | S2: 199.9 | T2: 191.2 | U2: 187.9 | V2: 190.8 | W2: 139.27097 | X2: 182.5 | Y2: 179.8 | Z2: 187.8 | AA2: 169.7 | AB2: 173.8 | AC2: 180.3 | AD2: 184.9 | AE2: 179.5 | AF2: 179.8 | AG2: 4447.271 | AH2: 718.5 | AI2: 379.1 | AJ2: 319.07097 | AK2: 2490.6 | AL2: 179.625 | AM2: 159.53548 | AN2: 177.9
A3: Urban | B3: 2023 | C3: May | D3: 45047 | E3: Post covid | F3: 174.7 | G3: 219.4 | H3: 176.7 | I3: 179.4 | J3: 164.4 | K3: 175.8 | L3: 185 | M3: 176.9 | N3: 124.2 | O3: 211.9 | P3: 165.9 | Q3: 197.7 | R3: 183.1 | S3: 204.2 | T3: 181.3 | U3: 168.1 | V3: 179.3 | W3: 175.6 | X3: 183.4 | Y3: 170.1 | Z3: 182.2 | AA3: 160.4 | AB3: 169.2 | AC3: 174.8 | AD3: 185.6 | AE3: 171.6 | AF3: 178.2 | AG3: 4461.6 | AH3: 701.2 | AI3: 349.4 | AJ3: 345.7 | AK3: 2539.3 | AL3: 175.3 | AM3: 172.85 | AN3: 181.37857
A4: Rural+Urban | B4: 2023 | C4: May | D4: 45047 | E4: Post covid | F4: 173.7 | G4: 214.3 | H4: 173.2 | I4: 179.5 | J4: 170 | K4: 172.2 | L4: 161 | M4: 175.6 | N4: 122.7 | O4: 218 | P4: 173.4 | Q4: 194.2 | R4: 179.1 | S4: 201 | T4: 187.3 | U4: 179.7 | V4: 186.2 | W4: 175.6 | X4: 182.8 | Y4: 175.2 | Z4: 185.7 | AA4: 164.8 | AB4: 171.2 | AC4: 177.1 | AD4: 185.2 | AE4: 175.7 | AF4: 179.1 | AG4: 4468.2 | AH4: 709.2 | AI4: 367 | AJ4: 350.8 | AK4: 2507.9 | AL4: 177.3 | AM4: 175.4 | AN4: 179.13571
F15: R+U | G15: Precentage | H15: Rural | I15: Precentage | J15: Urban | K15: Precentage
E16: Fuel and light | F16: 182.8 | G16: =F16/$F$23 -> 0.040909498 | H16: 182.5 | I16: =H16/$H$23 -> 0.041036134 | J16: 183.4 | K16: =J16/$J$23 -> 0.04110633
E17: Health | F17: 185.7 | G17: =F17/$F$23 -> 0.0415585 | H17: 187.8 | I17: =H17/$H$23 -> 0.042227869 | J17: 182.2 | K17: =J17/$J$23 -> 0.040837368
E18: Transport and communication | F18: 164.8 | G18: =F18/$F$23 -> 0.03688121 | H18: 169.7 | I18: =H18/$H$23 -> 0.038157983 | J18: 160.4 | K18: =J18/$J$23 -> 0.035951228
E19: sum of others | F19: 709.2 | G19: =F19/$F$23 -> 0.15871453 | H19: 718.5 | I19: =H19/$H$23 -> 0.1615587 | J19: 701.2 | K19: =J19/$J$23 -> 0.15716335
E20: sum of clothing | F20: 367 | G20: =F20/$F$23 -> 0.082132307 | H20: 379.1 | I20: =H20/$H$23 -> 0.085242732 | J20: 349.4 | K20: =J20/$J$23 -> 0.078312713
E21: Sum Housing Exepences | F21: 350.8 | G21: =F21/$F$23 -> 0.078506848 | H21: 319.07097 | I21: =H21/$H$23 -> 0.071744872 | J21: 345.7 | K21: =J21/$J$23 -> 0.077483414
E22: Sum of food expences | F22: 2507.9 | G22: =F22/$F$23 -> 0.56125235 | H22: 2490.6 | I22: =H22/$H$23 -> 0.56002518 | J22: 2539.3 | K22: =J22/$J$23 -> 0.5691456
E23: Total Expences | F23: 4468.4 | G23: =F23/$F$23 -> 1 | H23: 4447.3 | I23: =H23/$H$23 -> 1 | J23: 4461.6 | K23: =J23/$J$23 -> 1

Sheet Solution 2 
A2: Sector | B2: Rural+Urban
B4: Values
A5: Year | B5: Average of Average Food Expences | C5: Average of Fuel and light | D5: Average of Health
A6: 2021 | B6: 165.04881 | C6: 159.05833 | D6: 165.84167
A7: 2022 | B7: 174.14048 | C7: 175.13333 | D7: 175.925
A8: Grand Total | B8: 169.59464 | C8: 167.09583 | D8: 170.88333
A19: Sector | B19: Rural+Urban
A21: Average of General index
A22: Year | B22: Total
A23: 2017 | B23: 133.5
A24: 2018 | B24: 138.775
A25: 2019 | B25: 144.18182
A26: 2020 | B26: 153.38
A27: 2021 | B27: 161.45833
A28: 2022 | B28: 172.15
A29: 2023 | B29: 177.62
A30: Grand Total | B30: 152.41216
A35: Year | B35: Total | C35: % inflation
A36: 2017 | B36: 133.5
A37: 2018 | B37: 138.775 | C37: =(B37-B36)/B36 -> 0.039513109
A38: 2019 | B38: 144.18182 | C38: =(B38-B37)/B37 -> 0.038961039
A39: 2020 | B39: 153.38 | C39: =(B39-B38)/B38 -> 0.063795712
A40: 2021 | B40: 161.45833 | C40: =(B40-B39)/B39 -> 0.052668753
A41: 2022 | B41: 172.15 | C41: =(B41-B40)/B40 -> 0.066219355
A42: 2023 | B42: 177.62 | C42: =(B42-B41)/B41 -> 0.031774615

Sheet solution 3 
A1: Sector | B1: Year | C1: Month | D1: short month and year | E1: date | F1: Pre/Post Covid | G1: Cereals and products | H1: % change of cereals and product | I1: Meat and fish | J1: % change of meat | K1: Egg | L1: % change of egg | M1: Milk and products | N1: % change of milk and product | O1: Oils and fats | P1: % change of oil and fats | Q1: Fruits | R1: % change of fruits | S1: Vegetables | T1: % change of vegetable | U1: Pulses and products | V1: % change of pulses and products | W1: Sugar and Confectionery | X1: % change of sugar and conf | Y1: Spices | Z1: % change of spices | AA1: Non-alcoholic beverages | AB1: % change of non alcohol | AC1: Prepared meals, snacks, sweets etc. | AD1: % change of prepared | AE1: Food and beverages | AF1: % change of food and beverage | AG1: Pan, tobacco and intoxicants | AH1: % change of pan ,tobacoo | AI1: Clothing | AJ1: Footwear | AK1: Clothing and footwear | AL1: Housing | AM1: Fuel and light | AN1: Household goods and services | AO1: Health | AP1: Transport and communication | AQ1: Recreation and amusement | AR1: Education | AS1: Personal care and effects | AT1: Miscellaneous | AU1: General index | AV1: Total Expences | AW1: sum of others | AX1: sum of clothing | AY1: Sum Housing Exepences | AZ1: Sum of food expences | BA1: Average Other Expences | BB1: Average Housing Expences | BC1: Average Food Expences | BD1: Mom Change % | BE1: catagories | BF1: sum of catogories for rural | BG1: sum of catogories for urban | BH1: sum of catogories for R+U
A2: Rural | B2: 2022 | C2: June | D2: =TEXT(DATE(B2, MONTH(1&C2), 1), "mmm-yy") -> Jun-22 | E2: 44713 | F2: Post covid | G2: 153.8 | I2: 217.2 | K2: 169.6 | M2: 165.4 | O2: 208.1 | Q2: 165.8 | S2: 167.3 | U2: 164.6 | W2: 119.1 | Y2: 188.9 | AA2: 174.2 | AC2: 181.9 | AE2: 172.4 | AG2: 192.9 | AI2: 180.7 | AJ2: 178.7 | AK2: 180.4 | AL2: ='Handle missing value sheet only'!$C$1 -> 139.27097 | AM2: 176.7 | AN2: 170.3 | AO2: 178.2 | AP2: 165.5 | AQ2: 168 | AR2: 172.6 | AS2: 169.5 | AT2: 171 | AU2: 173.6 | AV2: =SUM(AL2:AT2,G2:AJ2) -> 4311.671 | AW2: =SUM(AT2,AS2,AR2,AQ2) -> 681.1 | AX2: =SUM(AJ2,AI2) -> 359.4 | AY2: =SUM(AN2,AL2) -> 309.57097 | AZ2: =SUM(G2:AG2) -> 2441.2 | BA2: =AVERAGE(AT2,AS2,AR2,AQ2) -> 170.275 | BB2: =AVERAGE(AL2,AN2) -> 154.78548 | BC2: 174.37143 | BE2: Cereals and products | BF2: =SUM(#REF!) -> #REF! | BG2: =SUM(#REF!) -> #REF! | BH2: =SUM(#REF!) -> #REF!
A3: Urban | B3: 2022 | C3: June | D3: =TEXT(DATE(B3, MONTH(1&C3), 1), "mmm-yy") -> Jun-22 | E3: 44713 | F3: Post covid | G3: 157.5 | I3: 223.4 | K3: 172.8 | M3: 166.4 | O3: 188.6 | Q3: 174.1 | S3: 211.5 | U3: 163.6 | W3: 121.4 | Y3: 183.5 | AA3: 159.1 | AC3: 186.3 | AE3: 179.3 | AG3: 198.3 | AI3: 171.6 | AJ3: 157.4 | AK3: 169.4 | AL3: 166.8 | AM3: 174.9 | AN3: 162.1 | AO3: 170.9 | AP3: 157.2 | AQ3: 164.1 | AR3: 166.5 | AS3: 169.2 | AT3: 163.8 | AU3: 171.4 | AV3: =SUM(AL3:AT3,G3:AJ3) -> 4310.3 | AW3: =SUM(AT3,AS3,AR3,AQ3) -> 663.6 | AX3: =SUM(AJ3,AI3) -> 329 | AY3: =SUM(AN3,AL3) -> 328.9 | AZ3: =SUM(G3:AG3) -> 2485.8 | BA3: =AVERAGE(AT3,AS3,AR3,AQ3) -> 165.9 | BB3: =AVERAGE(AL3,AN3) -> 164.45 | BC3: 177.55714 | BD3: =(BC3-BC2)/BC2 -> 0.018269703 | BE3: Meat and fish | BF3: =SUM(#REF!) -> #REF! | BG3: =SUM(#REF!) -> #REF! | BH3: =SUM(#REF!) -> #REF!
A4: Rural+Urban | B4: 2022 | C4: June | D4: =TEXT(DATE(B4, MONTH(1&C4), 1), "mmm-yy") -> Jun-22 | E4: 44713 | F4: Post covid | G4: 155 | I4: 219.4 | K4: 170.8 | M4: 165.8 | O4: 200.9 | Q4: 169.7 | S4: 182.3 | U4: 164.3 | W4: 119.9 | Y4: 187.1 | AA4: 167.9 | AC4: 183.9 | AE4: 174.9 | AG4: 194.3 | AI4: 177.1 | AJ4: 169.9 | AK4: 176 | AL4: 166.8 | AM4: 176 | AN4: 166.4 | AO4: 175.4 | AP4: 161.1 | AQ4: 165.8 | AR4: 169 | AS4: 169.4 | AT4: 167.5 | AU4: 172.6 | AV4: =SUM(AL4:AT4,G4:AJ4) -> 4320.6 | AW4: =SUM(AT4,AS4,AR4,AQ4) -> 671.7 | AX4: =SUM(AJ4,AI4) -> 347 | AY4: =SUM(AN4,AL4) -> 333.2 | AZ4: =SUM(G4:AG4) -> 2456.2 | BA4: =AVERAGE(AT4,AS4,AR4,AQ4) -> 167.925 | BB4: =AVERAGE(AL4,AN4) -> 166.6 | BC4: 175.44286 | BD4: =(BC4-BC3)/BC3 -> -0.011907635 | BE4: Egg | BF4: =SUM(#REF!) -> #REF! | BG4: =SUM(#REF!) -> #REF! | BH4: =SUM(#REF!) -> #REF!
A5: Rural | B5: 2022 | C5: July | D5: =TEXT(DATE(B5, MONTH(1&C5), 1), "mmm-yy") -> Jul-22 | E5: 44743 | F5: Post covid | G5: 155.2 | H5: =(G5-G2)/G2 -> 0.0091027308 | I5: 210.8 | J5: =(I5-I2)/I2 -> -0.02946593 | K5: 174.3 | L5: =(K5-K2)/K2 -> 0.027712264 | M5: 166.3 | N5: =(M5-M2)/M2 -> 0.0054413543 | O5: 202.2 | P5: =(O5-O2)/O2 -> -0.028351754 | Q5: 169.6 | R5: =(Q5-Q2)/Q2 -> 0.02291918 | S5: 168.6 | T5: =(S5-S2)/S2 -> 0.0077704722 | U5: 164.4 | V5: =(U5-U2)/U2 -> -0.0012150668 | W5: 119.2 | X5: =(W5-W2)/W2 -> 0.00083963056 | Y5: 191.8 | Z5: =(Y5-Y2)/Y2 -> 0.015352038 | AA5: 174.5 | AB5: =(AA5-AA2)/AA2 -> 0.0017221584 | AC5: 183.1 | AD5: =(AC5-AC2)/AC2 -> 0.0065970313 | AE5: 172.5 | AF5: =(AE5-AE2)/AE2 -> 0.0005800464 | AG5: 193.2 | AH5: =(AG5-AG2)/AG2 -> 0.00155521 | AI5: 182 | AJ5: 180.3 | AK5: 181.7 | AL5: ='Handle missing value sheet only'!$C$1 -> 139.27097 | AM5: 179.6 | AN5: 171.3 | AO5: 178.8 | AP5: 166.3 | AQ5: 168.6 | AR5: 174.7 | AS5: 169.7 | AT5: 171.8 | AU5: 174.3 | AV5: =SUM(AL5:AT5,G5:AJ5) -> 4328.1115 | AW5: =SUM(AT5,AS5,AR5,AQ5) -> 684.8 | AX5: =SUM(AJ5,AI5) -> 362.3 | AY5: =SUM(AN5,AL5) -> 310.57097 | AZ5: =SUM(G5:AG5) -> 2445.739 | BA5: =AVERAGE(AT5,AS5,AR5,AQ5) -> 171.2 | BB5: =AVERAGE(AL5,AN5) -> 155.28548 | BC5: 174.69286 | BD5: =(BC5-BC4)/BC4 -> -0.0042748962 | BE5: Milk and products | BF5: =SUM(#REF!) -> #REF! | BG5: =SUM(#REF!) -> #REF! | BH5: =SUM(#REF!) -> #REF!
A6: Urban | B6: 2022 | C6: July | D6: =TEXT(DATE(B6, MONTH(1&C6), 1), "mmm-yy") -> Jul-22 | E6: 44743 | F6: Post covid | G6: 159.3 | H6: =(G6-G3)/G3 -> 0.011428571 | I6: 217.1 | J6: =(I6-I3)/I3 -> -0.028200537 | K6: 176.6 | L6: =(K6-K3)/K3 -> 0.021990741 | M6: 167.1 | N6: =(M6-M3)/M3 -> 0.0042067308 | O6: 184.8 | P6: =(O6-O3)/O3 -> -0.020148462 | Q6: 179.5 | R6: =(Q6-Q3)/Q3 -> 0.031016657 | S6: 208.5 | T6: =(S6-S3)/S3 -> -0.014184397 | U6: 164 | V6: =(U6-U3)/U3 -> 0.0024449878 | W6: 121.5 | X6: =(W6-W3)/W3 -> 0.00082372323 | Y6: 186.3 | Z6: =(Y6-Y3)/Y3 -> 0.015258856 | AA6: 159.8 | AB6: =(AA6-AA3)/AA3 -> 0.0043997486 | AC6: 187.7 | AD6: =(AC6-AC3)/AC3 -> 0.0075147611 | AE6: 179.4 | AF6: =(AE6-AE3)/AE3 -> 0.00055772448 | AG6: 198.6 | AH6: =(AG6-AG3)/AG3 -> 0.0015128593 | AI6: 172.7 | AJ6: 158.7 | AK6: 170.6 | AL6: 167.8 | AM6: 179.5 | AN6: 163.1 | AO6: 171.7 | AP6: 157.4 | AQ6: 164.6 | AR6: 169.1 | AS6: 169.8 | AT6: 164.7 | AU6: 172.3 | AV6: =SUM(AL6:AT6,G6:AJ6) -> 4329.3386 | AW6: =SUM(AT6,AS6,AR6,AQ6) -> 668.2 | AX6: =SUM(AJ6,AI6) -> 331.4 | AY6: =SUM(AN6,AL6) -> 330.9 | AZ6: =SUM(G6:AG6) -> 2490.2371 | BA6: =AVERAGE(AT6,AS6,AR6,AQ6) -> 167.05 | BB6: =AVERAGE(AL6,AN6) -> 165.45 | BC6: 177.87143 | BD6: =(BC6-BC5)/BC5 -> 0.0181952 | BE6: Oils and fats | BF6: =SUM(#REF!) -> #REF! | BG6: =SUM(#REF!) -> #REF! | BH6: =SUM(#REF!) -> #REF!
A7: Rural+Urban | B7: 2022 | C7: July | D7: =TEXT(DATE(B7, MONTH(1&C7), 1), "mmm-yy") -> Jul-22 | E7: 44743 | F7: Post covid | G7: 156.5 | H7: =(G7-G4)/G4 -> 0.0096774194 | I7: 213 | J7: =(I7-I4)/I4 -> -0.029170465 | K7: 175.2 | L7: =(K7-K4)/K4 -> 0.025761124 | M7: 166.6 | N7: =(M7-M4)/M4 -> 0.0048250905 | O7: 195.8 | P7: =(O7-O4)/O4 -> -0.025385764 | Q7: 174.2 | R7: =(Q7-Q4)/Q4 -> 0.026517384 | S7: 182.1 | T7: =(S7-S4)/S4 -> -0.0010970927 | U7: 164.3 | V7: =(U7-U4)/U4 -> 0 | W7: 120 | X7: =(W7-W4)/W4 -> 0.00083402836 | Y7: 190 | Z7: =(Y7-Y4)/Y4 -> 0.015499733 | AA7: 168.4 | AB7: =(AA7-AA4)/AA4 -> 0.0029779631 | AC7: 185.2 | AD7: =(AC7-AC4)/AC4 -> 0.0070690593 | AE7: 175 | AF7: =(AE7-AE4)/AE4 -> 0.00057175529 | AG7: 194.6 | AH7: =(AG7-AG4)/AG4 -> 0.0015440041 | AI7: 178.3 | AJ7: 171.3 | AK7: 177.3 | AL7: 167.8 | AM7: 179.6 | AN7: 167.4 | AO7: 176.1 | AP7: 161.6 | AQ7: 166.3 | AR7: 171.4 | AS7: 169.7 | AT7: 168.4 | AU7: 173.4 | AV7: =SUM(AL7:AT7,G7:AJ7) -> 4338.8396 | AW7: =SUM(AT7,AS7,AR7,AQ7) -> 675.8 | AX7: =SUM(AJ7,AI7) -> 349.6 | AY7: =SUM(AN7,AL7) -> 335.2 | AZ7: =SUM(G7:AG7) -> 2460.9381 | BA7: =AVERAGE(AT7,AS7,AR7,AQ7) -> 168.95 | BB7: =AVERAGE(AL7,AN7) -> 167.6 | BC7: 175.77857 | BD7: =(BC7-BC6)/BC6 -> -0.011766123 | BE7: Fruits | BF7: =SUM(#REF!) -> #REF! | BG7: =SUM(#REF!) -> #REF! | BH7: =SUM(#REF!) -> #REF!
A8: Rural | B8: 2022 | C8: August | D8: =TEXT(DATE(B8, MONTH(1&C8), 1), "mmm-yy") -> Aug-22 | E8: 44774 | F8: Post covid | G8: 159.5 | H8: =(G8-G5)/G5 -> 0.027706186 | I8: 204.1 | J8: =(I8-I5)/I5 -> -0.031783681 | K8: 168.3 | L8: =(K8-K5)/K5 -> -0.034423408 | M8: 167.9 | N8: =(M8-M5)/M5 -> 0.0096211666 | O8: 198.1 | P8: =(O8-O5)/O5 -> -0.020276954 | Q8: 169.2 | R8: =(Q8-Q5)/Q5 -> -0.0023584906 | S8: 173.1 | T8: =(S8-S5)/S5 -> 0.026690391 | U8: 167.1 | V8: =(U8-U5)/U5 -> 0.016423358 | W8: 120.2 | X8: =(W8-W5)/W5 -> 0.0083892617 | Y8: 195.6 | Z8: =(Y8-Y5)/Y5 -> 0.019812304 | AA8: 174.8 | AB8: =(AA8-AA5)/AA5 -> 0.0017191977 | AC8: 184 | AD8: =(AC8-AC5)/AC5 -> 0.0049153468 | AE8: 173.9 | AF8: =(AE8-AE5)/AE5 -> 0.008115942 | AG8: 193.7 | AH8: =(AG8-AG5)/AG5 -> 0.0025879917 | AI8: 183.2 | AJ8: 181.7 | AK8: 183 | AL8: ='Handle missing value sheet only'!$C$1 -> 139.27097 | AM8: 179.1 | AN8: 172.3 | AO8: 179.4 | AP8: 166.6 | AQ8: 169.3 | AR8: 175.7 | AS8: 171.1 | AT8: 172.6 | AU8: 175.3 | AV8: =SUM(AL8:AT8,G8:AJ8) -> 4339.8081 | AW8: =SUM(AT8,AS8,AR8,AQ8) -> 688.7 | AX8: =SUM(AJ8,AI8) -> 364.9 | AY8: =SUM(AN8,AL8) -> 311.57097 | AZ8: =SUM(G8:AG8) -> 2449.5346 | BA8: =AVERAGE(AT8,AS8,AR8,AQ8) -> 172.175 | BB8: =AVERAGE(AL8,AN8) -> 155.78548 | BC8: 174.96429 | BD8: =(BC8-BC7)/BC7 -> -0.0046324515 | BE8: Vegetables | BF8: =SUM(#REF!) -> #REF! | BG8: =SUM(#REF!) -> #REF! | BH8: =SUM(#REF!) -> #REF!
A9: Urban | B9: 2022 | C9: August | D9: =TEXT(DATE(B9, MONTH(1&C9), 1), "mmm-yy") -> Aug-22 | E9: 44774 | F9: Post covid | G9: 162.1 | H9: =(G9-G6)/G6 -> 0.017576899 | I9: 210.9 | J9: =(I9-I6)/I6 -> -0.028558268 | K9: 170.6 | L9: =(K9-K6)/K6 -> -0.033975085 | M9: 168.4 | N9: =(M9-M6)/M6 -> 0.0077797726 | O9: 182.5 | P9: =(O9-O6)/O6 -> -0.012445887 | Q9: 177.1 | R9: =(Q9-Q6)/Q6 -> -0.013370474 | S9: 213.1 | T9: =(S9-S6)/S6 -> 0.02206235 | U9: 167.3 | V9: =(U9-U6)/U6 -> 0.020121951 | W9: 122.2 | X9: =(W9-W6)/W6 -> 0.0057613169 | Y9: 189.7 | Z9: =(Y9-Y6)/Y6 -> 0.018250134 | AA9: 160.5 | AB9: =(AA9-AA6)/AA6 -> 0.0043804756 | AC9: 188.9 | AD9: =(AC9-AC6)/AC6 -> 0.0063931806 | AE9: 180.4 | AF9: =(AE9-AE6)/AE6 -> 0.005574136 | AG9: 198.7 | AH9: =(AG9-AG6)/AG6 -> 0.00050352467 | AI9: 173.7 | AJ9: 160 | AK9: 171.6 | AL9: 169 | AM9: 178.4 | AN9: 164.2 | AO9: 172.6 | AP9: 157.7 | AQ9: 165.1 | AR9: 169.9 | AS9: 171.4 | AT9: 165.4 | AU9: 173.1 | AV9: =SUM(AL9:AT9,G9:AJ9) -> 4339.8201 | AW9: =SUM(AT9,AS9,AR9,AQ9) -> 671.8 | AX9: =SUM(AJ9,AI9) -> 333.7 | AY9: =SUM(AN9,AL9) -> 333.2 | AZ9: =SUM(G9:AG9) -> 2492.4196 | BA9: =AVERAGE(AT9,AS9,AR9,AQ9) -> 167.95 | BB9: =AVERAGE(AL9,AN9) -> 166.6 | BC9: 178.02857 | BD9: =(BC9-BC8)/BC8 -> 0.017513778 | BE9: Pulses and products | BF9: =SUM(#REF!) -> #REF! | BG9: =SUM(#REF!) -> #REF! | BH9: =SUM(#REF!) -> #REF!
A10: Rural+Urban | B10: 2022 | C10: August | D10: =TEXT(DATE(B10, MONTH(1&C10), 1), "mmm-yy") -> Aug-22 | E10: 44774 | F10: Post covid | G10: 160.3 | H10: =(G10-G7)/G7 -> 0.02428115 | I10: 206.5 | J10: =(I10-I7)/I7 -> -0.030516432 | K10: 169.2 | L10: =(K10-K7)/K7 -> -0.034246575 | M10: 168.1 | N10: =(M10-M7)/M7 -> 0.0090036014 | O10: 192.4 | P10: =(O10-O7)/O7 -> -0.017364658 | Q10: 172.9 | R10: =(Q10-Q7)/Q7 -> -0.0074626866 | S10: 186.7 | T10: =(S10-S7)/S7 -> 0.025260846 | U10: 167.2 | V10: =(U10-U7)/U7 -> 0.017650639 | W10: 120.9 | X10: =(W10-W7)/W7 -> 0.0075 | Y10: 193.6 | Z10: =(Y10-Y7)/Y7 -> 0.018947368 | AA10: 168.8 | AB10: =(AA10-AA7)/AA7 -> 0.0023752969 | AC10: 186.3 | AD10: =(AC10-AC7)/AC7 -> 0.0059395248 | AE10: 176.3 | AF10: =(AE10-AE7)/AE7 -> 0.0074285714 | AG10: 195 | AH10: =(AG10-AG7)/AG7 -> 0.0020554985 | AI10: 179.5 | AJ10: 172.7 | AK10: 178.5 | AL10: 169 | AM10: 178.8 | AN10: 168.5 | AO10: 176.8 | AP10: 161.9 | AQ10: 166.9 | AR10: 172.3 | AS10: 171.2 | AT10: 169.1 | AU10: 174.3 | AV10: =SUM(AL10:AT10,G10:AJ10) -> 4350.9309 | AW10: =SUM(AT10,AS10,AR10,AQ10) -> 679.5 | AX10: =SUM(AJ10,AI10) -> 352.2 | AY10: =SUM(AN10,AL10) -> 337.5 | AZ10: =SUM(G10:AG10) -> 2464.2288 | BA10: =AVERAGE(AT10,AS10,AR10,AQ10) -> 169.875 | BB10: =AVERAGE(AL10,AN10) -> 168.75 | BC10: 176.01429 | BD10: =(BC10-BC9)/BC9 -> -0.011314396 | BE10: Sugar and Confectionery | BF10: =SUM(#REF!) -> #REF! | BG10: =SUM(#REF!) -> #REF! | BH10: =SUM(#REF!) -> #REF!
A11: Rural | B11: 2022 | C11: September | D11: =TEXT(DATE(B11, MONTH(1&C11), 1), "mmm-yy") -> Sep-22 | E11: 44805 | F11: Post covid | G11: 162.9 | H11: =(G11-G8)/G8 -> 0.021316614 | I11: 206.7 | J11: =(I11-I8)/I8 -> 0.012738854 | K11: 169 | L11: =(K11-K8)/K8 -> 0.0041592395 | M11: 169.5 | N11: =(M11-M8)/M8 -> 0.0095294818 | O11: 194.1 | P11: =(O11-O8)/O8 -> -0.020191822 | Q11: 164.1 | R11: =(Q11-Q8)/Q8 -> -0.030141844 | S11: 176.9 | T11: =(S11-S8)/S8 -> 0.021952629 | U11: 169 | V11: =(U11-U8)/U8 -> 0.011370437 | W11: 120.8 | X11: =(W11-W8)/W8 -> 0.0049916805 | Y11: 199.1 | Z11: =(Y11-Y8)/Y8 -> 0.017893661 | AA11: 175.4 | AB11: =(AA11-AA8)/AA8 -> 0.0034324943 | AC11: 184.8 | AD11: =(AC11-AC8)/AC8 -> 0.0043478261 | AE11: 175.5 | AF11: =(AE11-AE8)/AE8 -> 0.0092006901 | AG11: 194.5 | AH11: =(AG11-AG8)/AG8 -> 0.0041300981 | AI11: 184.7 | AJ11: 183.3 | AK11: 184.5 | AL11: ='Handle missing value sheet only'!$C$1 -> 139.27097 | AM11: 179.7 | AN11: 173.6 | AO11: 180.2 | AP11: 166.9 | AQ11: 170 | AR11: 176.2 | AS11: 170.8 | AT11: 173.1 | AU11: 176.4 | AV11: =SUM(AL11:AT11,G11:AJ11) -> 4360.1457 | AW11: =SUM(AT11,AS11,AR11,AQ11) -> 690.1 | AX11: =SUM(AJ11,AI11) -> 368 | AY11: =SUM(AN11,AL11) -> 312.87097 | AZ11: =SUM(G11:AG11) -> 2462.3706 | BA11: =AVERAGE(AT11,AS11,AR11,AQ11) -> 172.525 | BB11: =AVERAGE(AL11,AN11) -> 156.43548 | BC11: 175.87857 | BD11: =(BC11-BC10)/BC10 -> -0.00077104131 | BE11: Spices | BF11: =SUM(#REF!) -> #REF! | BG11: =SUM(#REF!) -> #REF! | BH11: =SUM(#REF!) -> #REF!
A12: Urban | B12: 2022 | C12: September | D12: =TEXT(DATE(B12, MONTH(1&C12), 1), "mmm-yy") -> Sep-22 | E12: 44805 | F12: Post covid | G12: 164.9 | H12: =(G12-G9)/G9 -> 0.017273288 | I12: 213.7 | J12: =(I12-I9)/I9 -> 0.013276434 | K12: 170.9 | L12: =(K12-K9)/K9 -> 0.0017584994 | M12: 170.1 | N12: =(M12-M9)/M9 -> 0.010095012 | O12: 179.3 | P12: =(O12-O9)/O9 -> -0.017534247 | Q12: 167.5 | R12: =(Q12-Q9)/Q9 -> -0.054206663 | S12: 220.8 | T12: =(S12-S9)/S9 -> 0.036133271 | U12: 169.2 | V12: =(U12-U9)/U9 -> 0.011356844 | W12: 123.1 | X12: =(W12-W9)/W9 -> 0.0073649755 | Y12: 193.6 | Z12: =(Y12-Y9)/Y9 -> 0.020558777 | AA12: 161.1 | AB12: =(AA12-AA9)/AA9 -> 0.0037383178 | AC12: 190.4 | AD12: =(AC12-AC9)/AC9 -> 0.0079407094 | AE12: 181.8 | AF12: =(AE12-AE9)/AE9 -> 0.0077605322 | AG12: 199.7 | AH12: =(AG12-AG9)/AG9 -> 0.0050327126 | AI12: 175 | AJ12: 161.7 | AK12: 173 | AL12: 169.5 | AM12: 179.2 | AN12: 165 | AO12: 173.8 | AP12: 158.2 | AQ12: 165.8 | AR12: 170.9 | AS12: 171.1 | AT12: 166.1 | AU12: 174.1 | AV12: =SUM(AL12:AT12,G12:AJ12) -> 4362.4705 | AW12: =SUM(AT12,AS12,AR12,AQ12) -> 673.9 | AX12: =SUM(AJ12,AI12) -> 336.7 | AY12: =SUM(AN12,AL12) -> 334.5 | AZ12: =SUM(G12:AG12) -> 2506.1655 | BA12: =AVERAGE(AT12,AS12,AR12,AQ12) -> 168.475 | BB12: =AVERAGE(AL12,AN12) -> 167.25 | BC12: 179.00714 | BD12: =(BC12-BC11)/BC11 -> 0.017788247 | BE12: Non-alcoholic beverages | BF12: =SUM(#REF!) -> #REF! | BG12: =SUM(#REF!) -> #REF! | BH12: =SUM(#REF!) -> #REF!
A13: Rural+Urban | B13: 2022 | C13: September | D13: =TEXT(DATE(B13, MONTH(1&C13), 1), "mmm-yy") -> Sep-22 | E13: 44805 | F13: Post covid | G13: 163.5 | H13: =(G13-G10)/G10 -> 0.01996257 | I13: 209.2 | J13: =(I13-I10)/I10 -> 0.013075061 | K13: 169.7 | L13: =(K13-K10)/K10 -> 0.0029550827 | M13: 169.7 | N13: =(M13-M10)/M10 -> 0.009518144 | O13: 188.7 | P13: =(O13-O10)/O10 -> -0.019230769 | Q13: 165.7 | R13: =(Q13-Q10)/Q10 -> -0.041642568 | S13: 191.8 | T13: =(S13-S10)/S10 -> 0.027316551 | U13: 169.1 | V13: =(U13-U10)/U10 -> 0.011363636 | W13: 121.6 | X13: =(W13-W10)/W10 -> 0.005789909 | Y13: 197.3 | Z13: =(Y13-Y10)/Y10 -> 0.01911157 | AA13: 169.4 | AB13: =(AA13-AA10)/AA10 -> 0.0035545024 | AC13: 187.4 | AD13: =(AC13-AC10)/AC10 -> 0.0059044552 | AE13: 177.8 | AF13: =(AE13-AE10)/AE10 -> 0.0085082246 | AG13: 195.9 | AH13: =(AG13-AG10)/AG10 -> 0.0046153846 | AI13: 180.9 | AJ13: 174.3 | AK13: 179.9 | AL13: 169.5 | AM13: 179.5 | AN13: 169.5 | AO13: 177.8 | AP13: 162.3 | AQ13: 167.6 | AR13: 173.1 | AS13: 170.9 | AT13: 169.7 | AU13: 175.3 | AV13: =SUM(AL13:AT13,G13:AJ13) -> 4371.9708 | AW13: =SUM(AT13,AS13,AR13,AQ13) -> 681.3 | AX13: =SUM(AJ13,AI13) -> 355.2 | AY13: =SUM(AN13,AL13) -> 339 | AZ13: =SUM(G13:AG13) -> 2476.8662 | BA13: =AVERAGE(AT13,AS13,AR13,AQ13) -> 170.325 | BB13: =AVERAGE(AL13,AN13) -> 169.5 | BC13: 176.91429 | BD13: =(BC13-BC12)/BC12 -> -0.011691473 | BE13: Prepared meals, snacks, sweets etc. | BF13: =SUM(#REF!) -> #REF! | BG13: =SUM(#REF!) -> #REF! | BH13: =SUM(#REF!) -> #REF!
A14: Rural | B14: 2022 | C14: October | D14: =TEXT(DATE(B14, MONTH(1&C14), 1), "mmm-yy") -> Oct-22 | E14: 44835 | F14: Post covid | G14: 164.7 | H14: =(G14-G11)/G11 -> 0.011049724 | I14: 208.8 | J14: =(I14-I11)/I11 -> 0.010159652 | K14: 170.3 | L14: =(K14-K11)/K11 -> 0.0076923077 | M14: 170.9 | N14: =(M14-M11)/M11 -> 0.008259587 | O14: 191.6 | P14: =(O14-O11)/O11 -> -0.012879959 | Q14: 162.2 | R14: =(Q14-Q11)/Q11 -> -0.011578306 | S14: 184.8 | T14: =(S14-S11)/S11 -> 0.044657999 | U14: 169.7 | V14: =(U14-U11)/U11 -> 0.0041420118 | W14: 121.1 | X14: =(W14-W11)/W11 -> 0.0024834437 | Y14: 201.6 | Z14: =(Y14-Y11)/Y11 -> 0.012556504 | AA14: 175.8 | AB14: =(AA14-AA11)/AA11 -> 0.0022805017 | AC14: 185.6 | AD14: =(AC14-AC11)/AC11 -> 0.0043290043 | AE14: 177.4 | AF14: =(AE14-AE11)/AE11 -> 0.010826211 | AG14: 194.9 | AH14: =(AG14-AG11)/AG11 -> 0.0020565553 | AI14: 186.1 | AJ14: 184.4 | AK14: 185.9 | AL14: ='Handle missing value sheet only'!$C$1 -> 139.27097 | AM14: 180.8 | AN14: 174.4 | AO14: 181.2 | AP14: 167.4 | AQ14: 170.6 | AR14: 176.5 | AS14: 172 | AT14: 173.9 | AU14: 177.9 | AV14: =SUM(AL14:AT14,G14:AJ14) -> 4386.067 | AW14: =SUM(AT14,AS14,AR14,AQ14) -> 693 | AX14: =SUM(AJ14,AI14) -> 370.5 | AY14: =SUM(AN14,AL14) -> 313.67097 | AZ14: =SUM(G14:AG14) -> 2479.494 | BA14: =AVERAGE(AT14,AS14,AR14,AQ14) -> 173.25 | BB14: =AVERAGE(AL14,AN14) -> 156.83548 | BC14: 177.1 | BD14: =(BC14-BC13)/BC13 -> 0.0010497416 | BE14: Food and beverages | BF14: =SUM(#REF!) -> #REF! | BG14: =SUM(#REF!) -> #REF! | BH14: =SUM(#REF!) -> #REF!
A15: Urban | B15: 2022 | C15: October | D15: =TEXT(DATE(B15, MONTH(1&C15), 1), "mmm-yy") -> Oct-22 | E15: 44835 | F15: Post covid | G15: 166.4 | H15: =(G15-G12)/G12 -> 0.0090964221 | I15: 214.9 | J15: =(I15-I12)/I12 -> 0.0056153486 | K15: 171.9 | L15: =(K15-K12)/K12 -> 0.0058513751 | M15: 171 | N15: =(M15-M12)/M12 -> 0.0052910053 | O15: 177.7 | P15: =(O15-O12)/O12 -> -0.0089235917 | Q15: 165.7 | R15: =(Q15-Q12)/Q12 -> -0.010746269 | S15: 228.6 | T15: =(S15-S12)/S12 -> 0.035326087 | U15: 169.9 | V15: =(U15-U12)/U12 -> 0.0041371158 | W15: 123.4 | X15: =(W15-W12)/W12 -> 0.0024370431 | Y15: 196.4 | Z15: =(Y15-Y12)/Y12 -> 0.01446281 | AA15: 161.6 | AB15: =(AA15-AA12)/AA12 -> 0.0031036623 | AC15: 191.5 | AD15: =(AC15-AC12)/AC12 -> 0.0057773109 | AE15: 183.3 | AF15: =(AE15-AE12)/AE12 -> 0.0082508251 | AG15: 200.1 | AH15: =(AG15-AG12)/AG12 -> 0.0020030045 | AI15: 175.5 | AJ15: 162.6 | AK15: 173.6 | AL15: 171.2 | AM15: 180 | AN15: 166 | AO15: 174.7 | AP15: 158.8 | AQ15: 166.3 | AR15: 171.2 | AS15: 172.3 | AT15: 166.8 | AU15: 175.3 | AV15: =SUM(AL15:AT15,G15:AJ15) -> 4387.8817 | AW15: =SUM(AT15,AS15,AR15,AQ15) -> 676.6 | AX15: =SUM(AJ15,AI15) -> 338.1 | AY15: =SUM(AN15,AL15) -> 337.2 | AZ15: =SUM(G15:AG15) -> 2522.4797 | BA15: =AVERAGE(AT15,AS15,AR15,AQ15) -> 169.15 | BB15: =AVERAGE(AL15,AN15) -> 168.6 | BC15: 180.17143 | BD15: =(BC15-BC14)/BC14 -> 0.017342906 | BE15: Pan, tobacco and intoxicants | BF15: =SUM(#REF!) -> #REF! | BG15: =SUM(#REF!) -> #REF! | BH15: =SUM(#REF!) -> #REF!
